Workbook

Sheet 168
A1: =C2+'151'!C2 -> 410 | B1: موجودی کل | C1: =SUMPRODUCT(B3:B100,CU3:CU100) -> 43091 | D1: 45776 | E1: 45777 | F1: 4/31 | G1: 45778 | H1: 45779 | I1: 45780 | J1: 45781 | K1: 45782 | L1: 45783 | M1: 45784 | N1: 45785 | O1: 45786 | P1: 45787 | Q1: 45788 | R1: 45789 | S1: 45790 | T1: 45791 | U1: 45792 | V1: 45793 | W1: 45794 | X1: 45795 | Y1: 45796 | Z1: 45797 | AA1: 45798 | AB1: 45799 | AC1: 45800 | AD1: 45801 | AE1: 45802 | AF1: 45803 | AG1: 45804 | AH1: 45805 | AI1: 45806 | AJ1: 45807 | AK1: 45808 | AL1: 45809 | AM1: 45810 | AN1: 45811 | AO1: 45812 | AP1: 45813 | AQ1: 45814 | AR1: 45815 | AS1: 45816 | AT1: 45817 | AU1: 45818 | AV1: 45819 | AW1: 45820 | AX1: 45821 | AY1: 45822 | AZ1: 45823 | BA1: 45824 | BB1: 45825 | BC1: 45826 | BD1: 45827 | BE1: 45828 | BF1: 45829 | BG1: 45830 | BH1: 45831 | BI1: 45832 | BJ1: 45833 | BK1: 45834 | BL1: 45835 | BM1: 45836 | BN1: 45837 | BO1: 45838 | BP1: 6/31 | BQ1: 45839 | BR1: 45840 | BS1: 45841 | BT1: 45842 | BU1: 45843 | BV1: 45844 | BW1: 45845 | BX1: 45846 | BY1: 45847 | BZ1: 45848 | CA1: 45849 | CB1: 45850 | CC1: 45851 | CD1: 45852 | CE1: 45853 | CF1: 45854 | CG1: 45855 | CH1: 45856 | CI1: 45857 | CJ1: 45858 | CK1: 45859 | CL1: 45860 | CM1: 45861 | CN1: 45862 | CO1: 45863 | CP1: 45864 | CQ1: 45865 | CR1: 45866 | CS1: 45867 | CT1: 45868
A2: جمع فروش روزانه | B2: =SUM(B3:B100) -> 162 | C2: =sum(D2:CT2) -> 238 | D2: =sum(D3:D70) -> 2 | E2: =sum(E3:E70) -> 1 | F2: =sum(F3:F70) -> 7 | G2: =sum(G3:G70) -> 11 | H2: =sum(H3:H70) -> 6 | I2: =sum(I3:I70) -> 2 | J2: =sum(J3:J70) -> 7 | K2: =sum(K3:K70) -> 3 | ... CT2: =sum(CT3:CT70) -> 0
A3: فندی رضا | B3: =SUM(vorodi!B2:Z2)-C3-'151'!C3 -> 0 | C3: =sum(D3:CT3) -> 1 | D3: 1 | CU3: 948
A4: هوتیک سه سگک رضا | B4: =SUM(vorodi!B3:Z3)-C4-'151'!C4 -> 1 | C4: =sum(D4:CT4) -> 5 | AF4: 1 | AG4: 1 | AJ4: 1 | BB4: 1 | BR4: 1 | CU4: 915
A5: هرمس تخت رضا | B5: =SUM(vorodi!B4:Z4)-C5-'151'!C5 -> 1 | C5: =sum(D5:CT5) -> 4 | F5: 1 | N5: 1 | AB5: 1 | AD5: 1 | CU5: 468
A6: زارا جلو بسته رضا | B6: =SUM(vorodi!B5:Z5)-C6-'151'!C6 -> 0 | C6: =sum(D6:CT6) -> 1 | AH6: 1 | CU6: 920
A7: دو سگک ویزون رضا | B7: =SUM(vorodi!B6:Z6)-C7-'151'!C7 -> 0 | C7: =sum(D7:CT7) -> 1 | M7: 1 | CU7: 950
A8: استرادیواریوس جلو بسته رضا | B8: =SUM(vorodi!B11:Z11)-C8-'151'!C12 -> 0 | C8: =sum(D8:CT8) -> 6 | R8: 1 | X8: 1 | AH8: 1 | AL8: 1 | AN8: 1 | AX8: 1 | CU8: 958
A9: هرمس رکابدار پیام | B9: =SUM(vorodi!B7:Z7)-C9-'151'!C8 -> 5 | C9: =sum(D9:CT9) -> 2 | U9: 1 | BO9: 1 | CU9: 580
A10: هرمس چسبی پیام | B10: =SUM(vorodi!B8:Z8)-C10-'151'!C9 -> -4 | C10: =sum(D10:CT10) -> 8 | D10: 1 | F10: 1 | N10: 1 | AG10: 1 | AI10: 1 | AV10: 1 | AX10: 1 | CA10: 1 | CU10: 570
A11: سه بند زارا پیام | B11: =SUM(vorodi!B9:Z9)-C11-'151'!C10 -> 0 | C11: =sum(D11:CT11) -> 11 | F11: 1 | G11: 4 | H11: 3 | I11: 1 | M11: 1 | P11: 1 | CU11: 560
A12: دو سگک زارا پیام | B12: =SUM(vorodi!B10:Z10)-C12-'151'!C11 -> 0 | C12: =sum(D12:CT12) -> 8 | G12: 2 | H12: 1 | K12: 2 | R12: 1 | AB12: 1 | AH12: 1 | CU12: 580
A13: تک سگک پهن پیام | B13: =SUM(vorodi!B12:Z12)-C13-'151'!C13 -> 2 | C13: =sum(D13:CT13) -> 3 | E13: 1 | AB13: 1 | AM13: 1 | CU13: 650
A14: دو سگک قفل دار پیام | B14: =SUM(vorodi!B13:Z13)-C14-'151'!C14 -> -3 | C14: =sum(D14:CT14) -> 2 | F14: 1 | H14: 1 | CU14: 580
A15: دو سگک زیره کنف پیام | B15: =SUM(vorodi!B14:Z14)-C15-'151'!C15 -> 0 | C15: =sum(D15:CT15) -> 1 | K15: 1 | CU15: 720
A16: کنفی لژ بلند پیام | B16: =SUM(vorodi!B15:Z15)-C16-'151'!C16 -> 0 | C16: =sum(D16:CT16) -> 1 | AE16: 1 | CU16: 630
A17: دو سگک منگنه‌ای پیام | B17: =SUM(vorodi!B16:Z16)-C17-'151'!C17 -> 2 | C17: =sum(D17:CT17) -> 3 | AF17: 1 | AM17: 1 | BH17: 1 | CU17: 650
A18: گیوه گیپوری پوریا | B18: =SUM(vorodi!B17:Z17)-C18-'151'!C18 -> 1 | C18: =sum(D18:CT18) -> 1 | U18: 1 | CU18: 750
A19: دو سگک جلو مربعی پوریا | B19: =SUM(vorodi!B18:Z18)-C19-'151'!C19 -> 1 | C19: =sum(D19:CT19) -> 3 | AJ19: 1 | AN19: 1 | BL19: 1 | CU19: 380
A20: میو میو پوریا | B20: =SUM(vorodi!B19:Z19)-C20-'151'!C20 -> 1 | C20: =sum(D20:CT20) -> 1 | AR20: 1 | CU20: 920
A21: صندل جوکر پوریا | B21: =SUM(vorodi!B20:Z20)-C21-'151'!C21 -> 0 | C21: =sum(D21:CT21) -> 2 | M21: 1 | AY21: 1 | CU21: 695
A22: زارا لژ بزرگ پوریا | B22: =SUM(vorodi!B21:Z21)-C22-'151'!C22 -> -1 | C22: =sum(D22:CT22) -> 1 | G22: 1 | CU22: 970
A23: هرمس دور مچ مصطفی | B23: =SUM(vorodi!B22:Z22)-C23-'151'!C23 -> 1 | C23: =sum(D23:CT23) -> 9 | G23: 1 | J23: 2 | N23: 1 | O23: 2 | AA23: 1 | AE23: 1 | AL23: 1 | CU23: 650
A24: سه چسب مصطفی | B24: =SUM(vorodi!B23:Z23)-C24-'151'!C24 -> 2 | C24: =sum(D24:CT24) -> 5 | F24: 1 | G24: 1 | O24: 1 | AT24: 1 | CE24: 1 | CU24: 660
A25: دوپایی ضربدری مصطفی | B25: =SUM(vorodi!B24:Z24)-C25-'151'!C25 -> 1 | C25: =sum(D25:CT25) -> 1 | P25: 1 | CU25: 540
A26: دمپایی دو چسب مصطفی | B26: =SUM(vorodi!B25:Z25)-C26-'151'!C26 -> 1 | C26: =sum(D26:CT26) -> 2 | H26: 1 | BZ26: 1 | CU26: 660
A27: پاشنه شیشه‌ای | B27: =SUM(vorodi!B26:Z26)-C27-'151'!C27 -> 1 | C27: =sum(D27:CT27) -> 8 | O27: 1 | U27: 1 | AF27: 1 | BD27: 1 | BJ27: 1 | BK27: 1 | BL27: 1 | BU27: 1 | CU27: 580
A28: پاشنه۵سانت دو سگک | B28: =SUM(vorodi!B27:Z27)-C28-'151'!C28 -> 4 | C28: =sum(D28:CT28) -> 2 | AJ28: 1 | BE28: 1 | CU28: 750
A29: پاشنه چوبی هرمس | B29: =SUM(vorodi!B28:Z28)-C29-'151'!C29 -> 4 | C29: =sum(D29:CT29) -> 5 | I29: 1 | T29: 1 | AU29: 1 | AZ29: 1 | BO29: 1 | CU29: 858
A30: کتونی مکویین | B30: =SUM(vorodi!B29:Z29)-C30-'151'!C30 -> 2 | C30: =sum(D30:CT30) -> 7 | F30: 1 | M30: 1 | N30: 1 | AH30: 1 | AQ30: 1 | BV30: 1 | BZ30: 1 | CU30: 898
A31: ونس یرفا | B31: =SUM(vorodi!B30:Z30)-C31-'151'!C31 -> 10 | C31: =sum(D31:CT31) -> 6 | Y31: 1 | AY31: 2 | BA31: 1 | BB31: 1 | BH31: 1 | CU31: 550
A32: کتونی زارا پوریا | B32: =SUM(vorodi!B31:Z31)-C32-'151'!C32 -> -1 | C32: =sum(D32:CT32) -> 19 | J32: 2 | M32: 1 | AA32: 1 | AD32: 2 | AG32: 1 | AH32: 1 | AI32: 1 | AJ32: 1 | AK32: 1 | AN32: 1 | AP32: 1 | BI32: 1 | BJ32: 1 | BU32: 1 | BX32: 1 | BZ32: 1 | CG32: 1 | CU32: 690
A33: کتونی مرواریدی پوریا | B33: =SUM(vorodi!B32:Z32)-C33-'151'!C33 -> -1 | C33: =sum(D33:CT33) -> 3 | G33: 1 | AF33: 1 | AT33: 1 | CU33: 800
A34: کتونی سلین پوریا | B34: =SUM(vorodi!B33:Z33)-C34-'151'!C34 -> 5 | C34: =sum(D34:CT34) -> 9 | J34: 2 | O34: 1 | V34: 1 | W34: 1 | AH34: 1 | AX34: 1 | BA34: 1 | BH34: 1 | CU34: 500
A35: صندل کتونی بالنسیاگا | B35: =SUM(vorodi!B34:Z34)-C35-'151'!C35 -> 1 | C35: =sum(D35:CT35) -> 1 | G35: 1 | CU35: 890
A36: ونس برشکا ساده پیام | B36: =SUM(vorodi!B35:Z35)-C36-'151'!C36 -> 10 | C36: =sum(D36:CT36) -> 12 | J36: 1 | M36: 1 | X36: 1 | AI36: 1 | AU36: 1 | BA36: 2 | BG36: 1 | BK36: 1 | BT36: 1 | CG36: 1 | CK36: 1 | CU36: 750
A37: کتونی نیو بالانس پوریا | B37: =SUM(vorodi!B36:Z36)-C37-'151'!C37 -> 1 | C37: =sum(D37:CT37) -> 12 | L37: 1 | AD37: 1 | AQ37: 1 | AW37: 1 | AX37: 1 | BB37: 1 | BC37: 1 | BH37: 1 | BI37: 1 | BK37: 1 | BP37: 1 | CG37: 1 | CU37: 990
A38: کوک | B38: =SUM(vorodi!B37:Z37)-C38-'151'!C38 -> 1 | C38: =sum(D38:CT38) -> 6 | F38: 1 | AN38: 1 | AU38: 1 | AY38: 1 | BI38: 1 | BS38: 1 | CU38: 630
A39: مری جین ۵سانت | B39: =SUM(vorodi!B38:Z38)-C39-'151'!C39 -> 3 | C39: =sum(D39:CT39) -> 3 | O39: 1 | AO39: 1 | CA39: 1 | CU39: 858
A40: مری جین ۲سانت | B40: =SUM(vorodi!B39:Z39)-C40-'151'!C40 -> 2 | C40: =sum(D40:CT40) -> 2 | R40: 1 | U40: 1 | CU40: 798
...

Sheet 151
A1: =FB2 | B1: موجودی | C1: ='168'!C1 -> 43091 | D1: ='168'!D1 -> 45776 | E1: ='168'!E1 -> 45777 | F1: ='168'!F1 -> 4/31 | G1: ='168'!G1 -> 45778 | H1: ='168'!H1 -> 45779 | I1: ='168'!I1 -> 45780 | J1: ='168'!J1 -> 45781 | ... CT1: ='168'!CT1 -> 45868
A2: جمع فروش روزانه | C2: =sum(D2:CT2) -> 172 | D2: =sum(D3:D70) -> 1 | E2: =sum(E3:E70) -> 0 | F2: =sum(F3:F70) -> 3 | G2: =sum(G3:G70) -> 2 | H2: =sum(H3:H70) -> 3 | I2: =sum(I3:I70) -> 1 | J2: =sum(J3:J70) -> 0 | K2: =sum(K3:K70) -> 1 | ... CT2: =sum(CT3:CT70) -> 0
A3: ='168'!A3 -> فندی رضا | B3: ='168'!B3 -> 0 | C3: =sum(D3:CT3) -> 2 | H3: 1 | O3: 1
A4: ='168'!A4 -> هوتیک سه سگک رضا | B4: ='168'!B4 -> 1 | C4: =sum(D4:CT4) -> 0
A5: ='168'!A5 -> هرمس تخت رضا | B5: ='168'!B5 -> 1 | C5: =sum(D5:CT5) -> 3 | D5: 1 | M5: 1 | AI5: 1
A6: ='168'!A6 -> زارا جلو بسته رضا | B6: ='168'!B6 -> 0 | C6: =sum(D6:CT6) -> 6 | O6: 1 | Q6: 1 | S6: 1 | V6: 2 | X6: 1
A7: ='168'!A7 -> دو سگک ویزون رضا | B7: ='168'!B7 -> 0 | C7: =sum(D7:CT7) -> 0
A8: ='168'!A9 -> هرمس رکابدار پیام | B8: ='168'!B9 -> 5 | C8: =sum(D8:CT8) -> 3 | T8: 1 | AG8: 1 | AK8: 1
A9: ='168'!A10 -> هرمس چسبی پیام | B9: ='168'!B10 -> -4 | C9: =sum(D9:CT9) -> 7 | T9: 1 | AJ9: 1 | AS9: 1 | AU9: 1 | BH9: 1 | BK9: 1 | BX9: 1
A10: ='168'!A11 -> سه بند زارا پیام | B10: ='168'!B11 -> 0 | C10: =sum(D10:CT10) -> 1 | O10: 1
A11: ='168'!A12 -> دو سگک زارا پیام | B11: ='168'!B12 -> 0 | C11: =sum(D11:CT11) -> 4 | AB11: 1 | AD11: 1 | AH11: 1 | BA11: 1
A12: ='168'!A8 -> استرادیواریوس جلو بسته رضا | B12: ='168'!B8 -> 0 | C12: =sum(D12:CT12) -> 1 | AQ12: 1
A13: ='168'!A13 -> تک سگک پهن پیام | B13: ='168'!B13 -> 2 | C13: =sum(D13:CT13) -> 5 | W13: 1 | X13: 1 | AT13: 1 | BE13: 1 | BX13: 1
A14: ='168'!A14 -> دو سگک قفل دار پیام | B14: ='168'!B14 -> -3 | C14: =sum(D14:CT14) -> 3 | AL14: 1 | AV14: 1 | BJ14: 1
A15: ='168'!A15 -> دو سگک زیره کنف پیام | B15: ='168'!B15 -> 0 | C15: =sum(D15:CT15) -> 0
A16: ='168'!A16 -> کنفی لژ بلند پیام | B16: ='168'!B16 -> 0 | C16: =sum(D16:CT16) -> 1 | M16: 1
A17: ='168'!A17 -> دو سگک منگنه‌ای پیام | B17: ='168'!B17 -> 2 | C17: =sum(D17:CT17) -> 3 | F17: 1 | V17: 1 | Y17: 1
A18: ='168'!A18 -> گیوه گیپوری پوریا | B18: ='168'!B18 -> 1 | C18: =sum(D18:CT18) -> 0
A19: ='168'!A19 -> دو سگک جلو مربعی پوریا | B19: ='168'!B19 -> 1 | C19: =sum(D19:CT19) -> 0
A20: ='168'!A20 -> میو میو پوریا | B20: ='168'!B20 -> 1 | C20: =sum(D20:CT20) -> 1 | AE20: 1
A21: ='168'!A21 -> صندل جوکر پوریا | B21: ='168'!B21 -> 0 | C21: =sum(D21:CT21) -> 0
A22: ='168'!A22 -> زارا لژ بزرگ پوریا | B22: ='168'!B22 -> -1 | C22: =sum(D22:CT22) -> 1 | CD22: 1
A23: ='168'!A23 -> هرمس دور مچ مصطفی | B23: ='168'!B23 -> 1 | C23: =sum(D23:CT23) -> 2 | F23: 1 | L23: 1
A24: ='168'!A24 -> سه چسب مصطفی | B24: ='168'!B24 -> 2 | C24: =sum(D24:CT24) -> 0
A25: ='168'!A25 -> دوپایی ضربدری مصطفی | B25: ='168'!B25 -> 1 | C25: =sum(D25:CT25) -> 0
A26: ='168'!A26 -> دمپایی دو چسب مصطفی | B26: ='168'!B26 -> 1 | C26: =sum(D26:CT26) -> 1 | G26: 1
A27: ='168'!A27 -> پاشنه شیشه‌ای | B27: ='168'!B27 -> 1 | C27: =sum(D27:CT27) -> 4 | Q27: 2 | AV27: 1 | BW27: 1
A28: ='168'!A28 -> پاشنه۵سانت دو سگک | B28: ='168'!B28 -> 4 | C28: =sum(D28:CT28) -> 0
A29: ='168'!A29 -> پاشنه چوبی هرمس | B29: ='168'!B29 -> 4 | C29: =sum(D29:CT29) -> 2 | I29: 1 | AD29: 1
A30: ='168'!A30 -> کتونی مکویین | B30: ='168'!B30 -> 2 | C30: =sum(D30:CT30) -> 3 | K30: 1 | N30: 1 | AJ30: 1
A31: ='168'!A31 -> ونس یرفا | B31: ='168'!B31 -> 10 | C31: =sum(D31:CT31) -> 7 | H31: 1 | BC31: 1 | BN31: 1 | BX31: 1 | CE31: 1 | CG31: 1 | CH31: 1
A32: ='168'!A32 -> کتونی زارا پوریا | B32: ='168'!B32 -> -1 | C32: =sum(D32:CT32) -> 10 | H32: 1 | V32: 1 | BH32: 1 | BK32: 2 | BL32: 1 | BT32: 1 | BU32: 2 | BV32: 1
A33: ='168'!A33 -> کتونی مرواریدی پوریا | B33: ='168'!B33 -> -1 | C33: =sum(D33:CT33) -> 4 | AA33: 1 | AH33: 1 | AX33: 1 | BZ33: 1
A34: ='168'!A34 -> کتونی سلین پوریا | B34: ='168'!B34 -> 5 | C34: =sum(D34:CT34) -> 7 | V34: 1 | AJ34: 1 | AZ34: 1 | BB34: 1 | BF34: 1 | BH34: 1 | BT34: 1
A35: ='168'!A35 -> صندل کتونی بالنسیاگا | B35: ='168'!B35 -> 1 | C35: =sum(D35:CT35) -> 1 | AZ35: 1
A36: ='168'!A36 -> ونس برشکا ساده پیام | B36: ='168'!B36 -> 10 | C36: =sum(D36:CT36) -> 4 | BL36: 1 | BO36: 1 | BQ36: 1 | CG36: 1
A37: ='168'!A37 -> کتونی نیو بالانس پوریا | B37: ='168'!B37 -> 1 | C37: =sum(D37:CT37) -> 8 | G37: 1 | O37: 1 | W37: 1 | BG37: 1 | BO37: 1 | BQ37: 1 | BR37: 1 | CF37: 1
A38: ='168'!A38 -> کوک | B38: ='168'!B38 -> 1 | C38: =sum(D38:CT38) -> 5 | F38: 1 | P38: 1 | T38: 1 | W38: 1 | AL38: 1
A39: ='168'!A39 -> مری جین ۵سانت | B39: ='168'!B39 -> 3 | C39: =sum(D39:CT39) -> 2 | AQ39: 1 | AZ39: 1
A40: ='168'!A40 -> مری جین ۲سانت | B40: ='168'!B40 -> 2 | C40: =sum(D40:CT40) -> 1 | AU40: 1
...

Sheet vorodi
A1: =SUM(B2:Z100) -> 572 | B1: X | C1: X | D1: X | E1: X | F1: X | G1: X | H1: X | I1: X | J1: X | K1: X | L1: X
A2: ='168'!A3 -> فندی رضا | B2: 3
A3: ='168'!A4 -> هوتیک سه سگک رضا | B3: 6
A4: ='168'!A5 -> هرمس تخت رضا | B4: 8
A5: ='168'!A6 -> زارا جلو بسته رضا | B5: 7
A6: ='168'!A7 -> دو سگک ویزون رضا | B6: 1
A7: ='168'!A9 -> هرمس رکابدار پیام | B7: 10
A8: ='168'!A10 -> هرمس چسبی پیام | B8: 11
A9: ='168'!A11 -> سه بند زارا پیام | B9: 12
A10: ='168'!A12 -> دو سگک زارا پیام | B10: 12
A11: ='168'!A8 -> استرادیواریوس جلو بسته رضا | B11: 7
A12: ='168'!A13 -> تک سگک پهن پیام | B12: 10
A13: ='168'!A14 -> دو سگک قفل دار پیام | B13: 2
A14: ='168'!A15 -> دو سگک زیره کنف پیام | B14: 1
A15: ='168'!A16 -> کنفی لژ بلند پیام | B15: 2
A16: ='168'!A17 -> دو سگک منگنه‌ای پیام | B16: 8
A17: ='168'!A18 -> گیوه گیپوری پوریا | B17: 2
A18: ='168'!A19 -> دو سگک جلو مربعی پوریا | B18: 4
A19: ='168'!A20 -> میو میو پوریا | B19: 3
A20: ='168'!A21 -> صندل جوکر پوریا | B20: 2
A21: ='168'!A22 -> زارا لژ بزرگ پوریا | B21: 1
A22: ='168'!A23 -> هرمس دور مچ مصطفی | B22: 12
A23: ='168'!A24 -> سه چسب مصطفی | B23: 7
... A25: ='168'!A26 -> دمپایی دو چسب مصطفی | B25: 4
A26: ='168'!A27 -> پاشنه شیشه‌ای | B26: 7 | I26: 6
A27: ='168'!A28 -> پاشنه۵سانت دو سگک | B27: 6
A28: ='168'!A29 -> پاشنه چوبی هرمس | B28: 11
A29: ='168'!A30 -> کتونی مکویین | B29: 7 | D29: 5
A30: ='168'!A31 -> ونس یرفا | B30: 4 | E30: 1 | H30: 8 | M30: 10
A31: ='168'!A32 -> کتونی زارا پوریا | B31: 4 | C31: 5 | E31: 5 | I31: 9 | M31: 5
A32: ='168'!A33 -> کتونی مرواریدی پوریا | B32: 1 | E32: 5
A33: ='168'!A34 -> کتونی سلین پوریا | B33: 6 | C33: 10 | H33: 5
A34: ='168'!A35 -> صندل کتونی بالنسیاگا | B34: 3
A35: ='168'!A36 -> ونس برشکا ساده پیام | B35: 6 | H35: 20
A36: ='168'!A37 -> کتونی نیو بالانس پوریا | B36: 1 | C36: 4 | E36: 16
A37: ='168'!A38 -> کوک | B37: 12
A38: ='168'!A39 -> مری جین ۵سانت | B38: 8
A39: ='168'!A40 -> مری جین ۲سانت | B39: 5
A40: ='168'!A41 -> نایک y2k | C40: 10 | F40: 15
A41: ='168'!A42 -> سامبا | G41: 10 | I41: 10 | K41: 10
...
